<?xml version="1.0"?>
<robot name="scara_robot">
    <material name="blue">
        <color rgba="0.0 0.0 1.0 1.0"/>
    </material>
    <material name="black">
        <color rgba="0.0 0.0 0.0 1.0"/>
    </material>
    <material name="white">
        <color rgba="1.0 1.0 1.0 1.0"/>
    </material>



    <link name="world"/>



    <link name="base_link">
        <visual>
            <origin xyz="0.0 0.0 1.0" rpy="0.0 0.0 0.0"/>
            <geometry>
                <box size="1.0 1.0 0.1"/>
            </geometry>
            <material name="black"/>
        </visual>
    </link>
    <joint name="base_joint" type="fixed">
        <parent link="world"/>
        <child link="base_link"/>
    </joint>

    <link name="t1base_link">
        <visual>
            <origin xyz="0.4 0.4 0.4" rpy="0.0 0.0 0.0"/>
            <geometry>
                <cylinder length="1.1" radius="0.1"/>
            </geometry>
            <material name="blue"/>
        </visual>
    </link>
    <joint name="t1base_joint" type="fixed">
        <parent link="base_link"/>
        <child link="t1base_link"/>
    </joint>


    <link name="t2base_link">
        <visual>
            <origin xyz="-0.4 0.4 0.4" rpy="0.0 0.0 0.0"/>
            <geometry>
                <cylinder length="1.1" radius="0.1"/>
            </geometry>
            <material name="blue"/>
        </visual>
    </link>
    <joint name="t2base_joint" type="fixed">
        <parent link="base_link"/>
        <child link="t2base_link"/>
    </joint>

    <link name="t3base_link">
        <visual>
            <origin xyz="-0.4 -0.4 0.4" rpy="0.0 0.0 0.0"/>
            <geometry>
                <cylinder length="1.1" radius="0.1"/>
            </geometry>
            <material name="blue"/>
        </visual>
    </link>
    <joint name="t3base_joint" type="fixed">
        <parent link="base_link"/>
        <child link="t3base_link"/>
    </joint>

    <link name="t4base_link">
        <visual>
            <origin xyz="0.4 -0.4 0.4" rpy="0.0 0.0 0.0"/>
            <geometry>
                <cylinder length="1.1" radius="0.1"/>
            </geometry>
            <material name="blue"/>
        </visual>
    </link>
    <joint name="t4base_joint" type="fixed">
        <parent link="base_link"/>
        <child link="t4base_link"/>
    </joint>

    <link name="cy_link">
        <visual>
            <origin xyz="0.0 0.0 1.5" rpy="0.0 0.0 0.0"/>
            <geometry>
                <cylinder length="1.1" radius="0.1"/>
            </geometry>
            <material name="blue"/>
        </visual>
    </link>
    <joint name="cy_joint" type="continuous">
        <parent link="base_link"/>
        <child link="cy_link"/>
	<axis xyz="0.0 0.0 1.0"/>
        <limit lower="0" upper="6.283" effort="1000.0" velocity="1000.0"/>
    </joint>

    <link name="arm1">
        <visual>
            <origin xyz="0.0 -0.5 0.0" rpy="0.0 0.0 0.0"/>
            <geometry>
                <box size="0.1 1.0 0.1"/>
            </geometry>
            <material name="white"/>
        </visual>
    </link>
    <joint name="arm1_joint" type="revolute">
        <origin xyz="0.0 0.0 2.0" rpy="0.0 0.0 0.0"/>
        <parent link="cy_link"/>
        <child link="arm1"/>
        <axis xyz="0.0 0.0 1.0"/>
        <limit lower="-1.0" upper="1.0" effort="1000.0" velocity="1000.0"/>
    </joint>

    <link name="arm2">
        <visual>
            <origin xyz="0.0 -0.5 0.0" rpy="0.0 0.0 0.0"/>
            <geometry>
                <box size="0.1 1.0 0.1"/>
            </geometry>
            <material name="black"/>
        </visual>
    </link>
    <joint name="arm2_joint" type="revolute">
        <origin xyz="0.0 -1.0 0.0" rpy="0.0 0.0 0.0"/>
        <parent link="arm1"/>
        <child link="arm2"/>
        <axis xyz="1.0 0.0 0.0"/>
        <limit lower="-1.57" upper="1.57" effort="1000.0" velocity="1000.0"/>
    </joint>

    <link name="cy2_link">
        <visual>
            <origin xyz="0.0 -1.0 0.2" rpy="0.0 0.0 0.0"/>
            <geometry>
                <cylinder length="0.4" radius="0.1"/>
            </geometry>
            <material name="blue"/>
        </visual>
    </link>
    <joint name="cy2_joint" type="continuous">
        <parent link="arm2"/>
        <child link="cy2_link"/>
	<axis xyz="0.0 0.0 1.0"/>
        <limit lower="0" upper="6.283" effort="1000.0" velocity="1000.0"/>
    </joint>

   <link name="arm3">
        <visual>
            <origin xyz="0.0 -0.5 0.4" rpy="0.0 0.0 0.0"/>
            <geometry>
                <box size="0.1 1.0 0.1"/>
            </geometry>
            <material name="black"/>
        </visual>
    </link>
    <joint name="arm3_joint" type="revolute">
        <origin xyz="0.0 -1.0 0.0" rpy="0.0 0.0 0.0"/>
        <parent link="cy2_link"/>
        <child link="arm3"/>
        <axis xyz="0.0 0.0 1.0"/>
        <limit lower="-1.0" upper="1.0" effort="1000.0" velocity="1000.0"/>
    </joint>

    <link name="arm4">
        <visual>
            <origin xyz="0.0 -0.5 0.4" rpy="0.0 0.0 0.0"/>
            <geometry>
                <box size="0.1 1.0 0.1"/>
            </geometry>
            <material name="white"/>
        </visual>
    </link>
    <joint name="arm4_joint" type="revolute">
        <origin xyz="0.0 -1.0 0.0" rpy="0.0 0.0 0.0"/>
        <parent link="arm3"/>
        <child link="arm4"/>
        <axis xyz="0.0 0.0 1.0"/>
        <limit lower="-1.0" upper="1.0" effort="1000.0" velocity="1000.0"/>
    </joint>
    
	


   




</robot>