<?xml version="1.0" ?>
<robot name="diagonal_box_on_cylinder_robot" xmlns:xacro="http://ros.org/wiki/xacro">

  <!-- Define links -->
  <link name="base_link"/>

  <link name="cylinder_link">
    <visual>
      <geometry>
        <cylinder length="0.2" radius="0.05"/>
      </geometry>
    </visual>
    <collision>
      <geometry>
        <cylinder length="0.2" radius="0.05"/>
      </geometry>
    </collision>
    <inertial>
      <mass value="1.0"/>
      <inertia ixx="0.001" ixy="0.0" ixz="0.0" iyy="0.001" iyz="0.0" izz="0.001"/>
    </inertial>
  </link>

  <link name="box_link">
    <visual>
      <geometry>
        <box size="0.1 0.1 0.1"/>
      </geometry>
    </visual>
    <collision>
      <geometry>
        <box size="0.1 0.1 0.1"/>
      </geometry>
    </collision>
    <inertial>
      <mass value="1.0"/>
      <inertia ixx="0.001" ixy="0.0" ixz="0.0" iyy="0.001" iyz="0.0" izz="0.001"/>
    </inertial>
  </link>

  <!-- Define joints -->
  <joint name="cylinder_joint" type="fixed">
    <parent link="base_link"/>
    <child link="cylinder_link"/>
    <origin rpy="0 0 0" xyz="0 0 0.1"/>
  </joint>

  <joint name="box_joint" type="revolute">
    <parent link="cylinder_link"/>
    <child link="box_link"/>
    <origin rpy="0 0 0" xyz="0 0 0.15"/>
    <axis xyz="1 1 0"/>
    <limit effort="10" lower="-1.5708" upper="1.5708" velocity="0.5"/>
  </joint>

</robot>
