<?xml version="1.0" ?>
<robot name="slider_robot">

    <link name="base_link">
        <!-- Add visual, geometry, and material elements for the base link if needed -->
    </link>

    <link name="slider_link">
        <visual>
            <origin xyz="0 0 0" rpy="0 0 0"/>
            <geometry>
                <box size="1 0.1 0.1"/>
            </geometry>
            <material name="green"/>
        </visual>
    </link>

    <joint name="slider_joint" type="prismatic">
        <parent link="base_link"/>
        <child link="slider_link"/>
        <origin xyz="0 0 0" rpy="0 0 0"/>
        <axis xyz="1 0 0"/>
        <limit lower="-1" upper="1" effort="100" velocity="0.1"/>
    </joint>

</robot>
